<?xml version="1.0"?>
<robot name="line_follower">

	<material name="blue">
		<color rgba="0 0 0.8 1"/>
	</material>

	<material name="black">
		<color rgba="0 0 0 1"/>
	</material>

	<material name="white">
		<color rgba="1 1 1 1"/>
	</material>
	
	<link name="base_link">
		<visual>
			<geometry>
				<box size="4 2 0.5"/>
			</geometry>
			<material name="black"/>
		</visual>
		<collision>
			<geometry>
				<box size="4 2 0.5"/>
			</geometry>
		</collision>
		<inertial>
			<mass value="5"/>
			<inertia ixx="1.0" ixy="0.0" ixz="0.0" iyy="1.0" iyz="0.0" izz="1.0"/>
		</inertial>
	</link>

	<link name="right_front_wheel">
		<visual>
	  		<origin rpy="1.57075 0 0" xyz="0 0 0"/>
	      		<geometry>
				<cylinder length="0.2" radius="0.75"/>
	      		</geometry>
	      		<material name="white"/>
	    	</visual>
		<collision>
			<origin rpy="1.57075 0 0" xyz="0 0 0"/>
			<geometry>
				<cylinder length="0.2" radius="0.75"/>
			</geometry>
		</collision>
		<inertial>
			<mass value="1"/>
			<inertia ixx="1.0" ixy="0.0" ixz="0.0" iyy="1.0" iyz="0.0" izz="1.0"/>
		</inertial>
	</link>

	<joint name="right_front_wheel_joint" type="continuous">
		<axis rpy="0 0 0" xyz="0 1 0"/>
		<parent link="base_link"/>
		<child link="right_front_wheel"/>
		<origin rpy="0 0 0" xyz="1 -1.1 0"/>
	</joint>

	<link name="right_back_wheel">
		<visual>
	  		<origin rpy="1.57075 0 0" xyz="0 0 0"/>
	      		<geometry>
				<cylinder length="0.2" radius="0.75"/>
	      		</geometry>
	      		<material name="white"/>
	    	</visual>
		<collision>
			<origin rpy="1.57075 0 0" xyz="0 0 0"/>
			<geometry>
				<cylinder length="0.2" radius="0.75"/>
			</geometry>
		</collision>
		<inertial>
			<mass value="1"/>
			<inertia ixx="1.0" ixy="0.0" ixz="0.0" iyy="1.0" iyz="0.0" izz="1.0"/>
		</inertial>
	</link>

	<joint name="right_back_wheel_joint" type="continuous">
		<axis rpy="0 0 0" xyz="0 1 0"/>
		<parent link="base_link"/>
		<child link="right_back_wheel"/>
		<origin rpy="0 0 0" xyz="-1 -1.1 0"/>
	</joint>

	<link name="left_front_wheel">
		<visual>
	  		<origin rpy="1.57075 0 0" xyz="0 0 0"/>
	      		<geometry>
				<cylinder length="0.2" radius="0.75"/>
	      		</geometry>
	      		<material name="white"/>
	    	</visual>
		<collision>
			<origin rpy="1.57075 0 0" xyz="0 0 0"/>
			<geometry>
				<cylinder length="0.2" radius="0.75"/>
			</geometry>
		</collision>
		<inertial>
			<mass value="1"/>
			<inertia ixx="1.0" ixy="0.0" ixz="0.0" iyy="1.0" iyz="0.0" izz="1.0"/>
		</inertial>
	</link>

	<joint name="left_front_wheel_joint" type="continuous">
		<axis rpy="0 0 0" xyz="0 1 0"/>
		<parent link="base_link"/>
		<child link="left_front_wheel"/>
		<origin rpy="0 0 0" xyz="1 1.1 0"/>
	</joint>

	<link name="left_back_wheel">
		<visual>
	  		<origin rpy="1.57075 0 0" xyz="0 0 0"/>
	      		<geometry>
				<cylinder length="0.2" radius="0.75"/>
	      		</geometry>
	      		<material name="white"/>
	    	</visual>
		<collision>
			<origin rpy="1.57075 0 0" xyz="0 0 0"/>
			<geometry>
				<cylinder length="0.2" radius="0.75"/>
			</geometry>
		</collision>
		<inertial>
			<mass value="1"/>
			<inertia ixx="1.0" ixy="0.0" ixz="0.0" iyy="1.0" iyz="0.0" izz="1.0"/>
		</inertial>
	</link>

	<joint name="left_back_wheel_joint" type="continuous">
		<axis rpy="0 0 0" xyz="0 1 0"/>
		<parent link="base_link"/>
		<child link="left_back_wheel"/>
		<origin rpy="0 0 0" xyz="-1 1.1 0"/>
	</joint>

<link name="camera_link">
  <visual>
    <origin xyz="0 0 0" rpy="0 0 0"/>
   <geometry>
     <box size="0.05 0.05 0.05"/>
   </geometry>
   <material name="white"/>
   </visual>
 </link>

<joint name="camera_joint" type="fixed">
  <origin xyz="0.2 0 0.05" rpy="0 0 0"/>
  <parent link="base_link"/>
  <child link="camera_link"/>
</joint>

</robot>
